<?xml version="1.6"?> 
<sdf version="1.6">
  <model name="justbaked">
    <link name="base_link">
      <!-- ...existing code... -->
    </link>

    <!-- Chassis -->
    <link name="chassis">
      <visual name="chassis_visual">
        <pose>0 0 0.16666665 0 0 0</pose>
        <geometry>
          <box>
            <size>1.0 0.8 0.3333333</size>
          </box>
        </geometry>
        <material>
          <ambient>1.0 0.0 0.0 0.9</ambient>
          <diffuse>1.0 0.0 0.0 0.9</diffuse>
        </material>
      </visual>
      <collision name="chassis_collision">
        <pose>0 0 0.05 0 0 0</pose>
        <geometry>
          <box>
            <size>1.0 1.0 0.3333333</size>
          </box>
        </geometry>
      </collision>
      <inertial>
        <pose>0 0 0.16666665 0 0 0</pose>
        <mass>10.0</mass>
        <inertia>
          <ixx>0.625924</ixx>
          <ixy>0</ixy>
          <ixz>0</ixz>
          <iyy>1.36667</iyy>
          <iyz>0</iyz>
          <izz>0.92592</izz>
        </inertia>
      </inertial>
    </link>
    <joint name="chassis_joint" type="fixed">
      <parent>base_link</parent>
      <child>chassis</child>
      <pose>-0.1 0 0.1 0 0 0</pose>
    </joint>

    <!-- Front left wheel -->
    <link name="front_left_wheel">
      <visual name="front_left_wheel_visual">
        <pose>0 0 0 0 0 0</pose>
        <geometry>
          <cylinder>
            <radius>0.1</radius>
            <length>0.1</length>
          </cylinder>
        </geometry>
        <material>
          <ambient>0.0 0.0 0.0 1.0</ambient>
          <diffuse>0.0 0.0 0.0 1.0</diffuse>
        </material>
      </visual>
      <inertial>
        <pose>0 0 0 0 0 0</pose>
        <mass>1.0</mass>
        <inertia>
          <ixx>0.003333333</ixx>
          <ixy>0</ixy>
          <ixz>0</ixz>
          <iyy>0.003333333</iyy>
          <iyz>0</iyz>
          <izz>0.005</izz>
        </inertia>
      </inertial>
    </link>
    <joint name="front_left_wheel_joint" type="revolute">
      <parent>chassis</parent>
      <child>front_left_wheel</child>
      <pose>0.4 0.45 0.05 1.5708 0 0</pose>
      <axis>
        <xyz>0 0 1</xyz>
      </axis>
    </joint>

    <!-- Rear left wheel -->
    <link name="rear_left_wheel">
      <visual name="rear_left_wheel_visual">
        <pose>0 0 0 0 0 0</pose>
        <geometry>
          <cylinder>
            <radius>0.1</radius>
            <length>0.1</length>
          </cylinder>
        </geometry>
        <material>
          <ambient>0.0 0.0 0.0 1.0</ambient>
          <diffuse>0.0 0.0 0.0 1.0</diffuse>
        </material>
      </visual>
      <inertial>
        <pose>0 0 0 0 0 0</pose>
        <mass>1.0</mass>
        <inertia>
          <ixx>0.003333333</ixx>
          <ixy>0</ixy>
          <ixz>0</ixz>
          <iyy>0.003333333</iyy>
          <iyz>0</iyz>
          <izz>0.005</izz>
        </inertia>
      </inertial>
    </link>
    <joint name="rear_left_wheel_joint" type="revolute">
      <parent>chassis</parent>
      <child>rear_left_wheel</child>
      <pose>-0.4 0.45 0.05 1.5708 0 0</pose>
      <axis>
        <xyz>0 0 1</xyz>
      </axis>
    </joint>

    <!-- Front right wheel -->
    <link name="front_right_wheel">
      <visual name="front_right_wheel_visual">
        <pose>0 0 0 0 0 0</pose>
        <geometry>
          <cylinder>
            <radius>0.1</radius>
            <length>0.1</length>
          </cylinder>
        </geometry>
        <material>
          <ambient>0.0 0.0 0.0 1.0</ambient>
          <diffuse>0.0 0.0 0.0 1.0</diffuse>
        </material>
      </visual>
      <inertial>
        <pose>0 0 0 0 0 0</pose>
        <mass>1.0</mass>
        <inertia>
          <ixx>0.003333333</ixx>
          <ixy>0</ixy>
          <ixz>0</ixz>
          <iyy>0.003333333</iyy>
          <iyz>0</iyz>
          <izz>0.005</izz>
        </inertia>
      </inertial>
    </link>
    <joint name="front_right_wheel_joint" type="revolute">
      <parent>chassis</parent>
      <child>front_right_wheel</child>
      <pose>0.4 -0.45 0.05 1.5708 0 0</pose>
      <axis>
        <xyz>0 0 1</xyz>
      </axis>
    </joint>

    <!-- Rear right wheel -->
    <link name="rear_right_wheel">
      <visual name="rear_right_wheel_visual">
        <pose>0 0 0 0 0 0</pose>
        <geometry>
          <cylinder>
            <radius>0.1</radius>
            <length>0.1</length>
          </cylinder>
        </geometry>
        <material>
          <ambient>0.0 0.0 0.0 1.0</ambient>
          <diffuse>0.0 0.0 0.0 1.0</diffuse>
        </material>
      </visual>
      <inertial>
        <pose>0 0 0 0 0 0</pose>
        <mass>1.0</mass>
        <inertia>
          <ixx>0.003333333</ixx>
          <ixy>0</ixy>
          <ixz>0</ixz>
          <iyy>0.003333333</iyy>
          <iyz>0</iyz>
          <izz>0.005</izz>
        </inertia>
      </inertial>
    </link>
    <joint name="rear_right_wheel_joint" type="revolute">
      <parent>chassis</parent>
      <child>rear_right_wheel</child>
      <pose>-0.4 -0.45 0.05 1.5708 0 0</pose>
      <axis>
        <xyz>0 0 1</xyz>
      </axis>
    </joint>

    <!-- Lidar -->
    <link name="lidar">
      <visual name="lidar_visual">
        <pose>0 0 0 0 0 0</pose>
        <geometry>
          <cylinder>
            <radius>0.229659</radius>
            <length>0.0656168</length>
          </cylinder>
        </geometry>
        <material>
          <ambient>1.0 1.0 1.0 1.0</ambient>
          <diffuse>1.0 1.0 1.0 1.0</diffuse>
        </material>
      </visual>
      <inertial>
        <pose>0 0 0 0 0 0</pose>
        <mass>1.0</mass>
        <inertia>
          <ixx>0.013544611</ixx>
          <ixy>0</ixy>
          <ixz>0</ixz>
          <iyy>0.013544611</iyy>
          <iyz>0</iyz>
          <izz>0.026371628</izz>
        </inertia>
      </inertial>
    </link>
    <joint name="lidar_joint" type="revolute">
      <parent>chassis</parent>
      <child>lidar</child>
      <pose>0 0 0.3661417 0 0 0</pose>
      <axis>
        <xyz>0 0 1</xyz>
      </axis>
    </joint>
  </model>
</sdf>
