<robot name="sensor_rplidar" xmlns:xacro="http://ros.org/wiki/xacro">
	
	
	<!-- Lidar -->
<joint name="lidar_joint" type="continuous">
    <origin xyz="0.0 0.0 0.3661417" rpy="0.0 0.0 0.0"/>
    <parent link="chassis"/>
    <child link="lidar"/>
    <axis xyz="0.0 0.0 1.0"/>
</joint>

<link name="lidar">
    <visual name="lidar">
        <origin xyz="0.0 0.0 0.0" rpy="0.0 0.0 0.0"/>
        <geometry>
            <cylinder radius="0.229659" length="0.0656168"/>
        </geometry>
        <material name="white">
            <color rgba="1.0 1.0 1.0 1.0"/>
        </material>
    </visual>
	<collision>
		<origin xyz="0.0 0.0 0.0" rpy="0.0 0.0 0.0"/>
		<geometry>
			<cylinder radius="0.229659" length="0.0656168"/>
		</geometry>
	</collision>
    <inertial>
        <origin xyz="0.0 0.0 0.0" rpy="0.0 0.0 0.0"/>
        <mass value="1.0"/>
        <inertia ixx="0.013544611" ixy="0" ixz="0" iyy="0.013544611" iyz="0" izz="0.026371628"/>
    </inertial>
		<sensor type="gpu_ray" name="rplidar">
		<pose>0 0 0 0 0 0</pose>
		<always_on>true</always_on>
		<visualize>true</visualize>
		<update_rate>10</update_rate>
		<ray>
			<scan>
				<horizontal>
					<samples>400</samples>
					<resolution>1</resolution>
					<min_angle>-3.14159</min_angle>
					<max_angle>3.14159</max_angle>
				</horizontal>
			</scan>
			<range>
				<min>0.15</min>
				<max>6.0</max>
				<resolution>0.01</resolution>
			</range>
			<noise>
				<type>gaussian</type>
				<mean>0.0</mean>
				<stddev>0.01</stddev>
			</noise>
		</ray>
	</sensor>
</link>



</robot>