<robot name="sensor_rplidar" xmlns:xacro="http://ros.org/wiki/xacro">
	
    <!-- Lidar -->
<joint name="lidar_joint" type="continuous">
    <origin xyz="0.0 0.0 0.3661417" rpy="0.0 0.0 0.0"/>
    <parent link="chassis"/>
    <child link="lidar_link"/>
    <axis xyz="0.0 0.0 1.0"/>
</joint>


<link name="lidar_link">
    <visual name="lidar_link">
        <origin xyz="0.0 0.0 0.0" rpy="0.0 0.0 0.0"/>
        <geometry>
            <cylinder radius="0.229659" length="0.0656168"/>
        </geometry>
        <material name="white">
            <color rgba="1.0 1.0 1.0 1.0"/>
        </material>
    </visual>
	<collision>
		<origin xyz="0.0 0.0 0.0" rpy="0.0 0.0 0.0"/>
		<geometry>
			<cylinder radius="0.229659" length="0.0656168"/>
		</geometry>
	</collision>
    <inertial>
        <origin xyz="0.0 0.0 0.0" rpy="0.0 0.0 0.0"/>
        <mass value="1.0"/>
        <inertia ixx="0.013544611" ixy="0" ixz="0" iyy="0.013544611" iyz="0" izz="0.026371628"/>
    </inertial>
		
		    <gazebo reference="lidar">
      <sensor name="lidar_sensor" type="gpu_lidar">
        <topic>scan</topic>
        <update_rate>10</update_rate>
        <always_on>true</always_on>
        <visualize>true</visualize>
        <lidar>
          <scan>
            <horizontal>
              <samples>720</samples>
              <resolution>1</resolution>
              <min_angle>-3.14159</min_angle>
              <max_angle>3.14159</max_angle>
            </horizontal>
            <vertical>
              <samples>1</samples>
              <resolution>1</resolution>
              <min_angle>0</min_angle>
              <max_angle>0</max_angle>
            </vertical>
          </scan>
          <range>
            <min>0.2</min>
            <max>12</max>
            <resolution>0.013</resolution>
          </range>
        </lidar>
        <gz_frame_id>lidar</gz_frame_id>
      </sensor>
    </gazebo>

</link>



</robot>